 hugging face build log with 500 code
runtime error
Exit code: 3. Reason: line 146, in load_wsgi
    self.wsgi = self.app.wsgi()
                ^^^^^^^^^^^^^^^
  File "/usr/local/lib/python3.11/site-packages/gunicorn/app/base.py", line 67, in wsgi
    self.callable = self.load()
                    ^^^^^^^^^^^
  File "/usr/local/lib/python3.11/site-packages/gunicorn/app/wsgiapp.py", line 58, in load
    return self.load_wsgiapp()
           ^^^^^^^^^^^^^^^^^^^
  File "/usr/local/lib/python3.11/site-packages/gunicorn/app/wsgiapp.py", line 48, in load_wsgiapp
    return util.import_app(self.app_uri)
           ^^^^^^^^^^^^^^^^^^^^^^^^^^^^^
  File "/usr/local/lib/python3.11/site-packages/gunicorn/util.py", line 371, in import_app
    mod = importlib.import_module(module)
          ^^^^^^^^^^^^^^^^^^^^^^^^^^^^^^^
  File "/usr/local/lib/python3.11/importlib/__init__.py", line 126, in import_module
    return _bootstrap._gcd_import(name[level:], package, level)
           ^^^^^^^^^^^^^^^^^^^^^^^^^^^^^^^^^^^^^^^^^^^^^^^^^^^^
  File "<frozen importlib._bootstrap>", line 1204, in _gcd_import
  File "<frozen importlib._bootstrap>", line 1176, in _find_and_load
  File "<frozen importlib._bootstrap>", line 1147, in _find_and_load_unlocked
  File "<frozen importlib._bootstrap>", line 690, in _load_unlocked
  File "<frozen importlib._bootstrap_external>", line 940, in exec_module
  File "<frozen importlib._bootstrap>", line 241, in _call_with_frames_removed
  File "/app/app.py", line 167, in <module>
    analytics = PredictiveAnalytics()
                ^^^^^^^^^^^^^^^^^^^^^
  File "/app/app.py", line 59, in __init__
    os.makedirs(self.model_dir, exist_ok=True)
  File "<frozen os>", line 225, in makedirs
PermissionError: [Errno 13] Permission denied: 'models'
[2025-09-14 17:24:55 +0000] [8] [INFO] Worker exiting (pid: 8)
[2025-09-14 17:24:56 +0000] [6] [ERROR] Worker (pid:7) exited with code 3
[2025-09-14 17:24:56 +0000] [6] [ERROR] Worker (pid:8) was sent SIGTERM!
[2025-09-14 17:24:56 +0000] [6] [ERROR] Shutting down: Master
[2025-09-14 17:24:56 +0000] [6] [ERROR] Reason: Worker failed to boot.
Container logs:

===== Application Startup at 2025-09-14 17:21:07 =====

[2025-09-14 17:21:21 +0000] [7] [INFO] Starting gunicorn 21.2.0
[2025-09-14 17:21:21 +0000] [7] [INFO] Listening at: http://0.0.0.0:7860 (7)
[2025-09-14 17:21:21 +0000] [7] [INFO] Using worker: sync
[2025-09-14 17:21:21 +0000] [8] [INFO] Booting worker with pid: 8
[2025-09-14 17:21:21 +0000] [9] [INFO] Booting worker with pid: 9
WARNING:app:TensorFlow not available. Using simplified models.
[2025-09-14 17:21:22 +0000] [9] [ERROR] Exception in worker process
Traceback (most recent call last):
  File "/usr/local/lib/python3.11/site-packages/gunicorn/arbiter.py", line 609, in spawn_worker
    worker.init_process()
  File "/usr/local/lib/python3.11/site-packages/gunicorn/workers/base.py", line 134, in init_process
    self.load_wsgi()
  File "/usr/local/lib/python3.11/site-packages/gunicorn/workers/base.py", line 146, in load_wsgi
    self.wsgi = self.app.wsgi()
                ^^^^^^^^^^^^^^^
  File "/usr/local/lib/python3.11/site-packages/gunicorn/app/base.py", line 67, in wsgi
    self.callable = self.load()
                    ^^^^^^^^^^^
  File "/usr/local/lib/python3.11/site-packages/gunicorn/app/wsgiapp.py", line 58, in load
    return self.load_wsgiapp()
           ^^^^^^^^^^^^^^^^^^^
  File "/usr/local/lib/python3.11/site-packages/gunicorn/app/wsgiapp.py", line 48, in load_wsgiapp
    return util.import_app(self.app_uri)
           ^^^^^^^^^^^^^^^^^^^^^^^^^^^^^
  File "/usr/local/lib/python3.11/site-packages/gunicorn/util.py", line 371, in import_app
    mod = importlib.import_module(module)
          ^^^^^^^^^^^^^^^^^^^^^^^^^^^^^^^
  File "/usr/local/lib/python3.11/importlib/__init__.py", line 126, in import_module
    return _bootstrap._gcd_import(name[level:], package, level)
           ^^^^^^^^^^^^^^^^^^^^^^^^^^^^^^^^^^^^^^^^^^^^^^^^^^^^
  File "<frozen importlib._bootstrap>", line 1204, in _gcd_import
  File "<frozen importlib._bootstrap>", line 1176, in _find_and_load
  File "<frozen importlib._bootstrap>", line 1147, in _find_and_load_unlocked
  File "<frozen importlib._bootstrap>", line 690, in _load_unlocked
  File "<frozen importlib._bootstrap_external>", line 940, in exec_module
  File "<frozen importlib._bootstrap>", line 241, in _call_with_frames_removed
  File "/app/app.py", line 167, in <module>
    analytics = PredictiveAnalytics()
                ^^^^^^^^^^^^^^^^^^^^^
  File "/app/app.py", line 59, in __init__
    os.makedirs(self.model_dir, exist_ok=True)
  File "<frozen os>", line 225, in makedirs
PermissionError: [Errno 13] Permission denied: 'models'
[2025-09-14 17:21:22 +0000] [9] [INFO] Worker exiting (pid: 9)
WARNING:app:TensorFlow not available. Using simplified models.
[2025-09-14 17:21:22 +0000] [8] [ERROR] Exception in worker process
Traceback (most recent call last):
  File "/usr/local/lib/python3.11/site-packages/gunicorn/arbiter.py", line 609, in spawn_worker
    worker.init_process()
  File "/usr/local/lib/python3.11/site-packages/gunicorn/workers/base.py", line 134, in init_process
    self.load_wsgi()
  File "/usr/local/lib/python3.11/site-packages/gunicorn/workers/base.py", line 146, in load_wsgi
    self.wsgi = self.app.wsgi()
                ^^^^^^^^^^^^^^^
  File "/usr/local/lib/python3.11/site-packages/gunicorn/app/base.py", line 67, in wsgi
    self.callable = self.load()
                    ^^^^^^^^^^^
  File "/usr/local/lib/python3.11/site-packages/gunicorn/app/wsgiapp.py", line 58, in load
    return self.load_wsgiapp()
           ^^^^^^^^^^^^^^^^^^^
  File "/usr/local/lib/python3.11/site-packages/gunicorn/app/wsgiapp.py", line 48, in load_wsgiapp
    return util.import_app(self.app_uri)
           ^^^^^^^^^^^^^^^^^^^^^^^^^^^^^
  File "/usr/local/lib/python3.11/site-packages/gunicorn/util.py", line 371, in import_app
    mod = importlib.import_module(module)
          ^^^^^^^^^^^^^^^^^^^^^^^^^^^^^^^
  File "/usr/local/lib/python3.11/importlib/__init__.py", line 126, in import_module
    return _bootstrap._gcd_import(name[level:], package, level)
           ^^^^^^^^^^^^^^^^^^^^^^^^^^^^^^^^^^^^^^^^^^^^^^^^^^^^
  File "<frozen importlib._bootstrap>", line 1204, in _gcd_import
  File "<frozen importlib._bootstrap>", line 1176, in _find_and_load
  File "<frozen importlib._bootstrap>", line 1147, in _find_and_load_unlocked
  File "<frozen importlib._bootstrap>", line 690, in _load_unlocked
  File "<frozen importlib._bootstrap_external>", line 940, in exec_module
  File "<frozen importlib._bootstrap>", line 241, in _call_with_frames_removed
  File "/app/app.py", line 167, in <module>
    analytics = PredictiveAnalytics()
                ^^^^^^^^^^^^^^^^^^^^^
  File "/app/app.py", line 59, in __init__
    os.makedirs(self.model_dir, exist_ok=True)
  File "<frozen os>", line 225, in makedirs
PermissionError: [Errno 13] Permission denied: 'models'
[2025-09-14 17:21:22 +0000] [8] [INFO] Worker exiting (pid: 8)
[2025-09-14 17:21:23 +0000] [7] [ERROR] Worker (pid:8) exited with code 3
[2025-09-14 17:21:53 +0000] [7] [ERROR] Shutting down: Master
[2025-09-14 17:21:53 +0000] [7] [ERROR] Reason: Worker failed to boot.
[2025-09-14 17:21:54 +0000] [7] [INFO] Starting gunicorn 21.2.0
[2025-09-14 17:21:54 +0000] [7] [INFO] Listening at: http://0.0.0.0:7860 (7)
[2025-09-14 17:21:54 +0000] [7] [INFO] Using worker: sync
[2025-09-14 17:21:54 +0000] [8] [INFO] Booting worker with pid: 8
[2025-09-14 17:21:55 +0000] [9] [INFO] Booting worker with pid: 9
WARNING:app:TensorFlow not available. Using simplified models.
[2025-09-14 17:21:56 +0000] [8] [ERROR] Exception in worker process
Traceback (most recent call last):
  File "/usr/local/lib/python3.11/site-packages/gunicorn/arbiter.py", line 609, in spawn_worker
    worker.init_process()
  File "/usr/local/lib/python3.11/site-packages/gunicorn/workers/base.py", line 134, in init_process
    self.load_wsgi()
  File "/usr/local/lib/python3.11/site-packages/gunicorn/workers/base.py", line 146, in load_wsgi
    self.wsgi = self.app.wsgi()
                ^^^^^^^^^^^^^^^
  File "/usr/local/lib/python3.11/site-packages/gunicorn/app/base.py", line 67, in wsgi
    self.callable = self.load()
                    ^^^^^^^^^^^
  File "/usr/local/lib/python3.11/site-packages/gunicorn/app/wsgiapp.py", line 58, in load
    return self.load_wsgiapp()
           ^^^^^^^^^^^^^^^^^^^
  File "/usr/local/lib/python3.11/site-packages/gunicorn/app/wsgiapp.py", line 48, in load_wsgiapp
    return util.import_app(self.app_uri)
           ^^^^^^^^^^^^^^^^^^^^^^^^^^^^^
  File "/usr/local/lib/python3.11/site-packages/gunicorn/util.py", line 371, in import_app
    mod = importlib.import_module(module)
          ^^^^^^^^^^^^^^^^^^^^^^^^^^^^^^^
  File "/usr/local/lib/python3.11/importlib/__init__.py", line 126, in import_module
    return _bootstrap._gcd_import(name[level:], package, level)
           ^^^^^^^^^^^^^^^^^^^^^^^^^^^^^^^^^^^^^^^^^^^^^^^^^^^^
  File "<frozen importlib._bootstrap>", line 1204, in _gcd_import
  File "<frozen importlib._bootstrap>", line 1176, in _find_and_load
  File "<frozen importlib._bootstrap>", line 1147, in _find_and_load_unlocked
  File "<frozen importlib._bootstrap>", line 690, in _load_unlocked
  File "<frozen importlib._bootstrap_external>", line 940, in exec_module
  File "<frozen importlib._bootstrap>", line 241, in _call_with_frames_removed
  File "/app/app.py", line 167, in <module>
    analytics = PredictiveAnalytics()
                ^^^^^^^^^^^^^^^^^^^^^
  File "/app/app.py", line 59, in __init__
    os.makedirs(self.model_dir, exist_ok=True)
  File "<frozen os>", line 225, in makedirs
PermissionError: [Errno 13] Permission denied: 'models'
[2025-09-14 17:21:56 +0000] [8] [INFO] Worker exiting (pid: 8)
WARNING:app:TensorFlow not available. Using simplified models.
[2025-09-14 17:21:56 +0000] [9] [ERROR] Exception in worker process
Traceback (most recent call last):
  File "/usr/local/lib/python3.11/site-packages/gunicorn/arbiter.py", line 609, in spawn_worker
    worker.init_process()
  File "/usr/local/lib/python3.11/site-packages/gunicorn/workers/base.py", line 134, in init_process
    self.load_wsgi()
  File "/usr/local/lib/python3.11/site-packages/gunicorn/workers/base.py", line 146, in load_wsgi
    self.wsgi = self.app.wsgi()
                ^^^^^^^^^^^^^^^
  File "/usr/local/lib/python3.11/site-packages/gunicorn/app/base.py", line 67, in wsgi
    self.callable = self.load()
                    ^^^^^^^^^^^
  File "/usr/local/lib/python3.11/site-packages/gunicorn/app/wsgiapp.py", line 58, in load
    return self.load_wsgiapp()
           ^^^^^^^^^^^^^^^^^^^
  File "/usr/local/lib/python3.11/site-packages/gunicorn/app/wsgiapp.py", line 48, in load_wsgiapp
    return util.import_app(self.app_uri)
           ^^^^^^^^^^^^^^^^^^^^^^^^^^^^^
  File "/usr/local/lib/python3.11/site-packages/gunicorn/util.py", line 371, in import_app
    mod = importlib.import_module(module)
          ^^^^^^^^^^^^^^^^^^^^^^^^^^^^^^^
  File "/usr/local/lib/python3.11/importlib/__init__.py", line 126, in import_module
    return _bootstrap._gcd_import(name[level:], package, level)
           ^^^^^^^^^^^^^^^^^^^^^^^^^^^^^^^^^^^^^^^^^^^^^^^^^^^^
  File "<frozen importlib._bootstrap>", line 1204, in _gcd_import
  File "<frozen importlib._bootstrap>", line 1176, in _find_and_load
  File "<frozen importlib._bootstrap>", line 1147, in _find_and_load_unlocked
  File "<frozen importlib._bootstrap>", line 690, in _load_unlocked
  File "<frozen importlib._bootstrap_external>", line 940, in exec_module
  File "<frozen importlib._bootstrap>", line 241, in _call_with_frames_removed
  File "/app/app.py", line 167, in <module>
    analytics = PredictiveAnalytics()
                ^^^^^^^^^^^^^^^^^^^^^
  File "/app/app.py", line 59, in __init__
    os.makedirs(self.model_dir, exist_ok=True)
  File "<frozen os>", line 225, in makedirs
PermissionError: [Errno 13] Permission denied: 'models'
[2025-09-14 17:21:56 +0000] [9] [INFO] Worker exiting (pid: 9)
[2025-09-14 17:21:56 +0000] [7] [ERROR] Worker (pid:8) exited with code 3
[2025-09-14 17:21:56 +0000] [7] [ERROR] Worker (pid:9) was sent SIGTERM!
[2025-09-14 17:21:57 +0000] [7] [ERROR] Shutting down: Master
[2025-09-14 17:21:57 +0000] [7] [ERROR] Reason: Worker failed to boot.
[2025-09-14 17:22:12 +0000] [7] [INFO] Starting gunicorn 21.2.0
[2025-09-14 17:22:12 +0000] [7] [INFO] Listening at: http://0.0.0.0:7860 (7)
[2025-09-14 17:22:12 +0000] [7] [INFO] Using worker: sync
[2025-09-14 17:22:12 +0000] [8] [INFO] Booting worker with pid: 8
[2025-09-14 17:22:12 +0000] [9] [INFO] Booting worker with pid: 9
WARNING:app:TensorFlow not available. Using simplified models.
[2025-09-14 17:22:13 +0000] [8] [ERROR] Exception in worker process
Traceback (most recent call last):
  File "/usr/local/lib/python3.11/site-packages/gunicorn/arbiter.py", line 609, in spawn_worker
    worker.init_process()
  File "/usr/local/lib/python3.11/site-packages/gunicorn/workers/base.py", line 134, in init_process
    self.load_wsgi()
  File "/usr/local/lib/python3.11/site-packages/gunicorn/workers/base.py", line 146, in load_wsgi
    self.wsgi = self.app.wsgi()
                ^^^^^^^^^^^^^^^
  File "/usr/local/lib/python3.11/site-packages/gunicorn/app/base.py", line 67, in wsgi
    self.callable = self.load()
                    ^^^^^^^^^^^
  File "/usr/local/lib/python3.11/site-packages/gunicorn/app/wsgiapp.py", line 58, in load
    return self.load_wsgiapp()
           ^^^^^^^^^^^^^^^^^^^
  File "/usr/local/lib/python3.11/site-packages/gunicorn/app/wsgiapp.py", line 48, in load_wsgiapp
    return util.import_app(self.app_uri)
           ^^^^^^^^^^^^^^^^^^^^^^^^^^^^^
  File "/usr/local/lib/python3.11/site-packages/gunicorn/util.py", line 371, in import_app
    mod = importlib.import_module(module)
          ^^^^^^^^^^^^^^^^^^^^^^^^^^^^^^^
  File "/usr/local/lib/python3.11/importlib/__init__.py", line 126, in import_module
    return _bootstrap._gcd_import(name[level:], package, level)
           ^^^^^^^^^^^^^^^^^^^^^^^^^^^^^^^^^^^^^^^^^^^^^^^^^^^^
  File "<frozen importlib._bootstrap>", line 1204, in _gcd_import
  File "<frozen importlib._bootstrap>", line 1176, in _find_and_load
  File "<frozen importlib._bootstrap>", line 1147, in _find_and_load_unlocked
  File "<frozen importlib._bootstrap>", line 690, in _load_unlocked
  File "<frozen importlib._bootstrap_external>", line 940, in exec_module
  File "<frozen importlib._bootstrap>", line 241, in _call_with_frames_removed
  File "/app/app.py", line 167, in <module>
    analytics = PredictiveAnalytics()
                ^^^^^^^^^^^^^^^^^^^^^
  File "/app/app.py", line 59, in __init__
    os.makedirs(self.model_dir, exist_ok=True)
  File "<frozen os>", line 225, in makedirs
PermissionError: [Errno 13] Permission denied: 'models'
[2025-09-14 17:22:13 +0000] [8] [INFO] Worker exiting (pid: 8)
[2025-09-14 17:22:14 +0000] [7] [ERROR] Worker (pid:8) exited with code 3
WARNING:app:TensorFlow not available. Using simplified models.
[2025-09-14 17:22:14 +0000] [9] [ERROR] Exception in worker process
Traceback (most recent call last):
  File "/usr/local/lib/python3.11/site-packages/gunicorn/arbiter.py", line 609, in spawn_worker
    worker.init_process()
  File "/usr/local/lib/python3.11/site-packages/gunicorn/workers/base.py", line 134, in init_process
    self.load_wsgi()
  File "/usr/local/lib/python3.11/site-packages/gunicorn/workers/base.py", line 146, in load_wsgi
    self.wsgi = self.app.wsgi()
                ^^^^^^^^^^^^^^^
  File "/usr/local/lib/python3.11/site-packages/gunicorn/app/base.py", line 67, in wsgi
    self.callable = self.load()
                    ^^^^^^^^^^^
  File "/usr/local/lib/python3.11/site-packages/gunicorn/app/wsgiapp.py", line 58, in load
    return self.load_wsgiapp()
           ^^^^^^^^^^^^^^^^^^^
  File "/usr/local/lib/python3.11/site-packages/gunicorn/app/wsgiapp.py", line 48, in load_wsgiapp
    return util.import_app(self.app_uri)
           ^^^^^^^^^^^^^^^^^^^^^^^^^^^^^
  File "/usr/local/lib/python3.11/site-packages/gunicorn/util.py", line 371, in import_app
    mod = importlib.import_module(module)
          ^^^^^^^^^^^^^^^^^^^^^^^^^^^^^^^
  File "/usr/local/lib/python3.11/importlib/__init__.py", line 126, in import_module
    return _bootstrap._gcd_import(name[level:], package, level)
           ^^^^^^^^^^^^^^^^^^^^^^^^^^^^^^^^^^^^^^^^^^^^^^^^^^^^
  File "<frozen importlib._bootstrap>", line 1204, in _gcd_import
  File "<frozen importlib._bootstrap>", line 1176, in _find_and_load
  File "<frozen importlib._bootstrap>", line 1147, in _find_and_load_unlocked
  File "<frozen importlib._bootstrap>", line 690, in _load_unlocked
  File "<frozen importlib._bootstrap_external>", line 940, in exec_module
  File "<frozen importlib._bootstrap>", line 241, in _call_with_frames_removed
  File "/app/app.py", line 167, in <module>
    analytics = PredictiveAnalytics()
                ^^^^^^^^^^^^^^^^^^^^^
  File "/app/app.py", line 59, in __init__
    os.makedirs(self.model_dir, exist_ok=True)
  File "<frozen os>", line 225, in makedirs
PermissionError: [Errno 13] Permission denied: 'models'
[2025-09-14 17:22:14 +0000] [9] [INFO] Worker exiting (pid: 9)
[2025-09-14 17:22:14 +0000] [7] [ERROR] Worker (pid:9) exited with code 3
Traceback (most recent call last):
  File "/usr/local/lib/python3.11/site-packages/gunicorn/arbiter.py", line 209, in run
    self.sleep()
  File "/usr/local/lib/python3.11/site-packages/gunicorn/arbiter.py", line 360, in sleep
    ready = select.select([self.PIPE[0]], [], [], 1.0)
            ^^^^^^^^^^^^^^^^^^^^^^^^^^^^^^^^^^^^^^^^^^
  File "/usr/local/lib/python3.11/site-packages/gunicorn/arbiter.py", line 242, in handle_chld
    self.reap_workers()
  File "/usr/local/lib/python3.11/site-packages/gunicorn/arbiter.py", line 530, in reap_workers
    raise HaltServer(reason, self.WORKER_BOOT_ERROR)
gunicorn.errors.HaltServer: <HaltServer 'Worker failed to boot.' 3>

During handling of the above exception, another exception occurred:

Traceback (most recent call last):
  File "/usr/local/bin/gunicorn", line 8, in <module>
    sys.exit(run())
             ^^^^^
  File "/usr/local/lib/python3.11/site-packages/gunicorn/app/wsgiapp.py", line 67, in run
    WSGIApplication("%(prog)s [OPTIONS] [APP_MODULE]").run()
  File "/usr/local/lib/python3.11/site-packages/gunicorn/app/base.py", line 236, in run
    super().run()
  File "/usr/local/lib/python3.11/site-packages/gunicorn/app/base.py", line 72, in run
    Arbiter(self).run()
  File "/usr/local/lib/python3.11/site-packages/gunicorn/arbiter.py", line 229, in run
    self.halt(reason=inst.reason, exit_status=inst.exit_status)
  File "/usr/local/lib/python3.11/site-packages/gunicorn/arbiter.py", line 342, in halt
    self.stop()
  File "/usr/local/lib/python3.11/site-packages/gunicorn/arbiter.py", line 396, in stop
    time.sleep(0.1)
  File "/usr/local/lib/python3.11/site-packages/gunicorn/arbiter.py", line 242, in handle_chld
    self.reap_workers()
  File "/usr/local/lib/python3.11/site-packages/gunicorn/arbiter.py", line 530, in reap_workers
    raise HaltServer(reason, self.WORKER_BOOT_ERROR)
gunicorn.errors.HaltServer: <HaltServer 'Worker failed to boot.' 3>
[2025-09-14 17:22:44 +0000] [6] [INFO] Starting gunicorn 21.2.0
[2025-09-14 17:22:44 +0000] [6] [INFO] Listening at: http://0.0.0.0:7860 (6)
[2025-09-14 17:22:44 +0000] [6] [INFO] Using worker: sync
[2025-09-14 17:22:44 +0000] [7] [INFO] Booting worker with pid: 7
[2025-09-14 17:22:44 +0000] [8] [INFO] Booting worker with pid: 8
WARNING:app:TensorFlow not available. Using simplified models.
[2025-09-14 17:22:45 +0000] [7] [ERROR] Exception in worker process
Traceback (most recent call last):
  File "/usr/local/lib/python3.11/site-packages/gunicorn/arbiter.py", line 609, in spawn_worker
    worker.init_process()
  File "/usr/local/lib/python3.11/site-packages/gunicorn/workers/base.py", line 134, in init_process
    self.load_wsgi()
  File "/usr/local/lib/python3.11/site-packages/gunicorn/workers/base.py", line 146, in load_wsgi
    self.wsgi = self.app.wsgi()
                ^^^^^^^^^^^^^^^
  File "/usr/local/lib/python3.11/site-packages/gunicorn/app/base.py", line 67, in wsgi
    self.callable = self.load()
                    ^^^^^^^^^^^
  File "/usr/local/lib/python3.11/site-packages/gunicorn/app/wsgiapp.py", line 58, in load
    return self.load_wsgiapp()
           ^^^^^^^^^^^^^^^^^^^
  File "/usr/local/lib/python3.11/site-packages/gunicorn/app/wsgiapp.py", line 48, in load_wsgiapp
    return util.import_app(self.app_uri)
           ^^^^^^^^^^^^^^^^^^^^^^^^^^^^^
  File "/usr/local/lib/python3.11/site-packages/gunicorn/util.py", line 371, in import_app
    mod = importlib.import_module(module)
          ^^^^^^^^^^^^^^^^^^^^^^^^^^^^^^^
  File "/usr/local/lib/python3.11/importlib/__init__.py", line 126, in import_module
    return _bootstrap._gcd_import(name[level:], package, level)
           ^^^^^^^^^^^^^^^^^^^^^^^^^^^^^^^^^^^^^^^^^^^^^^^^^^^^
  File "<frozen importlib._bootstrap>", line 1204, in _gcd_import
  File "<frozen importlib._bootstrap>", line 1176, in _find_and_load
  File "<frozen importlib._bootstrap>", line 1147, in _find_and_load_unlocked
  File "<frozen importlib._bootstrap>", line 690, in _load_unlocked
  File "<frozen importlib._bootstrap_external>", line 940, in exec_module
  File "<frozen importlib._bootstrap>", line 241, in _call_with_frames_removed
  File "/app/app.py", line 167, in <module>
    analytics = PredictiveAnalytics()
                ^^^^^^^^^^^^^^^^^^^^^
  File "/app/app.py", line 59, in __init__
    os.makedirs(self.model_dir, exist_ok=True)
  File "<frozen os>", line 225, in makedirs
PermissionError: [Errno 13] Permission denied: 'models'
[2025-09-14 17:22:45 +0000] [7] [INFO] Worker exiting (pid: 7)
WARNING:app:TensorFlow not available. Using simplified models.
[2025-09-14 17:22:46 +0000] [8] [ERROR] Exception in worker process
Traceback (most recent call last):
  File "/usr/local/lib/python3.11/site-packages/gunicorn/arbiter.py", line 609, in spawn_worker
    worker.init_process()
  File "/usr/local/lib/python3.11/site-packages/gunicorn/workers/base.py", line 134, in init_process
    self.load_wsgi()
  File "/usr/local/lib/python3.11/site-packages/gunicorn/workers/base.py", line 146, in load_wsgi
    self.wsgi = self.app.wsgi()
                ^^^^^^^^^^^^^^^
  File "/usr/local/lib/python3.11/site-packages/gunicorn/app/base.py", line 67, in wsgi
    self.callable = self.load()
                    ^^^^^^^^^^^
  File "/usr/local/lib/python3.11/site-packages/gunicorn/app/wsgiapp.py", line 58, in load
    return self.load_wsgiapp()
           ^^^^^^^^^^^^^^^^^^^
  File "/usr/local/lib/python3.11/site-packages/gunicorn/app/wsgiapp.py", line 48, in load_wsgiapp
    return util.import_app(self.app_uri)
           ^^^^^^^^^^^^^^^^^^^^^^^^^^^^^
  File "/usr/local/lib/python3.11/site-packages/gunicorn/util.py", line 371, in import_app
    mod = importlib.import_module(module)
          ^^^^^^^^^^^^^^^^^^^^^^^^^^^^^^^
  File "/usr/local/lib/python3.11/importlib/__init__.py", line 126, in import_module
    return _bootstrap._gcd_import(name[level:], package, level)
           ^^^^^^^^^^^^^^^^^^^^^^^^^^^^^^^^^^^^^^^^^^^^^^^^^^^^
  File "<frozen importlib._bootstrap>", line 1204, in _gcd_import
  File "<frozen importlib._bootstrap>", line 1176, in _find_and_load
  File "<frozen importlib._bootstrap>", line 1147, in _find_and_load_unlocked
  File "<frozen importlib._bootstrap>", line 690, in _load_unlocked
  File "<frozen importlib._bootstrap_external>", line 940, in exec_module
  File "<frozen importlib._bootstrap>", line 241, in _call_with_frames_removed
  File "/app/app.py", line 167, in <module>
    analytics = PredictiveAnalytics()
                ^^^^^^^^^^^^^^^^^^^^^
  File "/app/app.py", line 59, in __init__
    os.makedirs(self.model_dir, exist_ok=True)
  File "<frozen os>", line 225, in makedirs
PermissionError: [Errno 13] Permission denied: 'models'
[2025-09-14 17:22:46 +0000] [8] [INFO] Worker exiting (pid: 8)
[2025-09-14 17:22:46 +0000] [6] [ERROR] Worker (pid:7) exited with code 3
[2025-09-14 17:22:46 +0000] [6] [ERROR] Worker (pid:8) was sent SIGTERM!
[2025-09-14 17:22:46 +0000] [6] [ERROR] Shutting down: Master
[2025-09-14 17:22:46 +0000] [6] [ERROR] Reason: Worker failed to boot.
[2025-09-14 17:23:29 +0000] [6] [INFO] Starting gunicorn 21.2.0
[2025-09-14 17:23:29 +0000] [6] [INFO] Listening at: http://0.0.0.0:7860 (6)
[2025-09-14 17:23:29 +0000] [6] [INFO] Using worker: sync
[2025-09-14 17:23:29 +0000] [7] [INFO] Booting worker with pid: 7
[2025-09-14 17:23:29 +0000] [8] [INFO] Booting worker with pid: 8
WARNING:app:TensorFlow not available. Using simplified models.
[2025-09-14 17:23:31 +0000] [7] [ERROR] Exception in worker process
Traceback (most recent call last):
  File "/usr/local/lib/python3.11/site-packages/gunicorn/arbiter.py", line 609, in spawn_worker
    worker.init_process()
  File "/usr/local/lib/python3.11/site-packages/gunicorn/workers/base.py", line 134, in init_process
    self.load_wsgi()
  File "/usr/local/lib/python3.11/site-packages/gunicorn/workers/base.py", line 146, in load_wsgi
    self.wsgi = self.app.wsgi()
                ^^^^^^^^^^^^^^^
  File "/usr/local/lib/python3.11/site-packages/gunicorn/app/base.py", line 67, in wsgi
    self.callable = self.load()
                    ^^^^^^^^^^^
  File "/usr/local/lib/python3.11/site-packages/gunicorn/app/wsgiapp.py", line 58, in load
    return self.load_wsgiapp()
           ^^^^^^^^^^^^^^^^^^^
  File "/usr/local/lib/python3.11/site-packages/gunicorn/app/wsgiapp.py", line 48, in load_wsgiapp
    return util.import_app(self.app_uri)
           ^^^^^^^^^^^^^^^^^^^^^^^^^^^^^
  File "/usr/local/lib/python3.11/site-packages/gunicorn/util.py", line 371, in import_app
    mod = importlib.import_module(module)
          ^^^^^^^^^^^^^^^^^^^^^^^^^^^^^^^
  File "/usr/local/lib/python3.11/importlib/__init__.py", line 126, in import_module
    return _bootstrap._gcd_import(name[level:], package, level)
           ^^^^^^^^^^^^^^^^^^^^^^^^^^^^^^^^^^^^^^^^^^^^^^^^^^^^
  File "<frozen importlib._bootstrap>", line 1204, in _gcd_import
  File "<frozen importlib._bootstrap>", line 1176, in _find_and_load
  File "<frozen importlib._bootstrap>", line 1147, in _find_and_load_unlocked
  File "<frozen importlib._bootstrap>", line 690, in _load_unlocked
  File "<frozen importlib._bootstrap_external>", line 940, in exec_module
  File "<frozen importlib._bootstrap>", line 241, in _call_with_frames_removed
  File "/app/app.py", line 167, in <module>
    analytics = PredictiveAnalytics()
                ^^^^^^^^^^^^^^^^^^^^^
  File "/app/app.py", line 59, in __init__
    os.makedirs(self.model_dir, exist_ok=True)
  File "<frozen os>", line 225, in makedirs
PermissionError: [Errno 13] Permission denied: 'models'
[2025-09-14 17:23:31 +0000] [7] [INFO] Worker exiting (pid: 7)
WARNING:app:TensorFlow not available. Using simplified models.
[2025-09-14 17:23:31 +0000] [8] [ERROR] Exception in worker process
Traceback (most recent call last):
  File "/usr/local/lib/python3.11/site-packages/gunicorn/arbiter.py", line 609, in spawn_worker
    worker.init_process()
  File "/usr/local/lib/python3.11/site-packages/gunicorn/workers/base.py", line 134, in init_process
    self.load_wsgi()
  File "/usr/local/lib/python3.11/site-packages/gunicorn/workers/base.py", line 146, in load_wsgi
    self.wsgi = self.app.wsgi()
                ^^^^^^^^^^^^^^^
  File "/usr/local/lib/python3.11/site-packages/gunicorn/app/base.py", line 67, in wsgi
    self.callable = self.load()
                    ^^^^^^^^^^^
  File "/usr/local/lib/python3.11/site-packages/gunicorn/app/wsgiapp.py", line 58, in load
    return self.load_wsgiapp()
           ^^^^^^^^^^^^^^^^^^^
  File "/usr/local/lib/python3.11/site-packages/gunicorn/app/wsgiapp.py", line 48, in load_wsgiapp
    return util.import_app(self.app_uri)
           ^^^^^^^^^^^^^^^^^^^^^^^^^^^^^
  File "/usr/local/lib/python3.11/site-packages/gunicorn/util.py", line 371, in import_app
    mod = importlib.import_module(module)
          ^^^^^^^^^^^^^^^^^^^^^^^^^^^^^^^
  File "/usr/local/lib/python3.11/importlib/__init__.py", line 126, in import_module
    return _bootstrap._gcd_import(name[level:], package, level)
           ^^^^^^^^^^^^^^^^^^^^^^^^^^^^^^^^^^^^^^^^^^^^^^^^^^^^
  File "<frozen importlib._bootstrap>", line 1204, in _gcd_import
  File "<frozen importlib._bootstrap>", line 1176, in _find_and_load
  File "<frozen importlib._bootstrap>", line 1147, in _find_and_load_unlocked
  File "<frozen importlib._bootstrap>", line 690, in _load_unlocked
  File "<frozen importlib._bootstrap_external>", line 940, in exec_module
  File "<frozen importlib._bootstrap>", line 241, in _call_with_frames_removed
  File "/app/app.py", line 167, in <module>
    analytics = PredictiveAnalytics()
                ^^^^^^^^^^^^^^^^^^^^^
  File "/app/app.py", line 59, in __init__
    os.makedirs(self.model_dir, exist_ok=True)
  File "<frozen os>", line 225, in makedirs
PermissionError: [Errno 13] Permission denied: 'models'
[2025-09-14 17:23:31 +0000] [8] [INFO] Worker exiting (pid: 8)
[2025-09-14 17:23:31 +0000] [6] [ERROR] Worker (pid:7) exited with code 3
[2025-09-14 17:23:31 +0000] [6] [ERROR] Worker (pid:8) was sent SIGTERM!
[2025-09-14 17:23:31 +0000] [6] [ERROR] Shutting down: Master
[2025-09-14 17:23:31 +0000] [6] [ERROR] Reason: Worker failed to boot.
[2025-09-14 17:24:54 +0000] [6] [INFO] Starting gunicorn 21.2.0
[2025-09-14 17:24:54 +0000] [6] [INFO] Listening at: http://0.0.0.0:7860 (6)
[2025-09-14 17:24:54 +0000] [6] [INFO] Using worker: sync
[2025-09-14 17:24:54 +0000] [7] [INFO] Booting worker with pid: 7
[2025-09-14 17:24:54 +0000] [8] [INFO] Booting worker with pid: 8
WARNING:app:TensorFlow not available. Using simplified models.
[2025-09-14 17:24:55 +0000] [7] [ERROR] Exception in worker process
Traceback (most recent call last):
  File "/usr/local/lib/python3.11/site-packages/gunicorn/arbiter.py", line 609, in spawn_worker
    worker.init_process()
  File "/usr/local/lib/python3.11/site-packages/gunicorn/workers/base.py", line 134, in init_process
    self.load_wsgi()
  File "/usr/local/lib/python3.11/site-packages/gunicorn/workers/base.py", line 146, in load_wsgi
    self.wsgi = self.app.wsgi()
                ^^^^^^^^^^^^^^^
  File "/usr/local/lib/python3.11/site-packages/gunicorn/app/base.py", line 67, in wsgi
    self.callable = self.load()
                    ^^^^^^^^^^^
  File "/usr/local/lib/python3.11/site-packages/gunicorn/app/wsgiapp.py", line 58, in load
    return self.load_wsgiapp()
           ^^^^^^^^^^^^^^^^^^^
  File "/usr/local/lib/python3.11/site-packages/gunicorn/app/wsgiapp.py", line 48, in load_wsgiapp
    return util.import_app(self.app_uri)
           ^^^^^^^^^^^^^^^^^^^^^^^^^^^^^
  File "/usr/local/lib/python3.11/site-packages/gunicorn/util.py", line 371, in import_app
    mod = importlib.import_module(module)
          ^^^^^^^^^^^^^^^^^^^^^^^^^^^^^^^
  File "/usr/local/lib/python3.11/importlib/__init__.py", line 126, in import_module
    return _bootstrap._gcd_import(name[level:], package, level)
           ^^^^^^^^^^^^^^^^^^^^^^^^^^^^^^^^^^^^^^^^^^^^^^^^^^^^
  File "<frozen importlib._bootstrap>", line 1204, in _gcd_import
  File "<frozen importlib._bootstrap>", line 1176, in _find_and_load
  File "<frozen importlib._bootstrap>", line 1147, in _find_and_load_unlocked
  File "<frozen importlib._bootstrap>", line 690, in _load_unlocked
  File "<frozen importlib._bootstrap_external>", line 940, in exec_module
  File "<frozen importlib._bootstrap>", line 241, in _call_with_frames_removed
  File "/app/app.py", line 167, in <module>
    analytics = PredictiveAnalytics()
                ^^^^^^^^^^^^^^^^^^^^^
  File "/app/app.py", line 59, in __init__
    os.makedirs(self.model_dir, exist_ok=True)
  File "<frozen os>", line 225, in makedirs
PermissionError: [Errno 13] Permission denied: 'models'
[2025-09-14 17:24:55 +0000] [7] [INFO] Worker exiting (pid: 7)
WARNING:app:TensorFlow not available. Using simplified models.
[2025-09-14 17:24:55 +0000] [8] [ERROR] Exception in worker process
Traceback (most recent call last):
  File "/usr/local/lib/python3.11/site-packages/gunicorn/arbiter.py", line 609, in spawn_worker
    worker.init_process()
  File "/usr/local/lib/python3.11/site-packages/gunicorn/workers/base.py", line 134, in init_process
    self.load_wsgi()
  File "/usr/local/lib/python3.11/site-packages/gunicorn/workers/base.py", line 146, in load_wsgi
    self.wsgi = self.app.wsgi()
                ^^^^^^^^^^^^^^^
  File "/usr/local/lib/python3.11/site-packages/gunicorn/app/base.py", line 67, in wsgi
    self.callable = self.load()
                    ^^^^^^^^^^^
  File "/usr/local/lib/python3.11/site-packages/gunicorn/app/wsgiapp.py", line 58, in load
    return self.load_wsgiapp()
           ^^^^^^^^^^^^^^^^^^^
  File "/usr/local/lib/python3.11/site-packages/gunicorn/app/wsgiapp.py", line 48, in load_wsgiapp
    return util.import_app(self.app_uri)
           ^^^^^^^^^^^^^^^^^^^^^^^^^^^^^
  File "/usr/local/lib/python3.11/site-packages/gunicorn/util.py", line 371, in import_app
    mod = importlib.import_module(module)
          ^^^^^^^^^^^^^^^^^^^^^^^^^^^^^^^
  File "/usr/local/lib/python3.11/importlib/__init__.py", line 126, in import_module
    return _bootstrap._gcd_import(name[level:], package, level)
           ^^^^^^^^^^^^^^^^^^^^^^^^^^^^^^^^^^^^^^^^^^^^^^^^^^^^
  File "<frozen importlib._bootstrap>", line 1204, in _gcd_import
  File "<frozen importlib._bootstrap>", line 1176, in _find_and_load
  File "<frozen importlib._bootstrap>", line 1147, in _find_and_load_unlocked
  File "<frozen importlib._bootstrap>", line 690, in _load_unlocked
  File "<frozen importlib._bootstrap_external>", line 940, in exec_module
  File "<frozen importlib._bootstrap>", line 241, in _call_with_frames_removed
  File "/app/app.py", line 167, in <module>
    analytics = PredictiveAnalytics()
                ^^^^^^^^^^^^^^^^^^^^^
  File "/app/app.py", line 59, in __init__
    os.makedirs(self.model_dir, exist_ok=True)
  File "<frozen os>", line 225, in makedirs
PermissionError: [Errno 13] Permission denied: 'models'
[2025-09-14 17:24:55 +0000] [8] [INFO] Worker exiting (pid: 8)
[2025-09-14 17:24:56 +0000] [6] [ERROR] Worker (pid:7) exited with code 3
[2025-09-14 17:24:56 +0000] [6] [ERROR] Worker (pid:8) was sent SIGTERM!
[2025-09-14 17:24:56 +0000] [6] [ERROR] Shutting down: Master
[2025-09-14 17:24:56 +0000] [6] [ERROR] Reason: Worker failed to boot.
[2025-09-14 17:27:40 +0000] [6] [INFO] Starting gunicorn 21.2.0
[2025-09-14 17:27:40 +0000] [6] [INFO] Listening at: http://0.0.0.0:7860 (6)
[2025-09-14 17:27:40 +0000] [6] [INFO] Using worker: sync
[2025-09-14 17:27:40 +0000] [7] [INFO] Booting worker with pid: 7
[2025-09-14 17:27:40 +0000] [8] [INFO] Booting worker with pid: 8
WARNING:app:TensorFlow not available. Using simplified models.
WARNING:app:TensorFlow not available. Using simplified models.
[2025-09-14 17:27:45 +0000] [7] [ERROR] Exception in worker process
Traceback (most recent call last):
  File "/usr/local/lib/python3.11/site-packages/gunicorn/arbiter.py", line 609, in spawn_worker
    worker.init_process()
  File "/usr/local/lib/python3.11/site-packages/gunicorn/workers/base.py", line 134, in init_process
    self.load_wsgi()
  File "/usr/local/lib/python3.11/site-packages/gunicorn/workers/base.py", line 146, in load_wsgi
    self.wsgi = self.app.wsgi()
                ^^^^^^^^^^^^^^^
  File "/usr/local/lib/python3.11/site-packages/gunicorn/app/base.py", line 67, in wsgi
    self.callable = self.load()
                    ^^^^^^^^^^^
  File "/usr/local/lib/python3.11/site-packages/gunicorn/app/wsgiapp.py", line 58, in load
    return self.load_wsgiapp()
           ^^^^^^^^^^^^^^^^^^^
  File "/usr/local/lib/python3.11/site-packages/gunicorn/app/wsgiapp.py", line 48, in load_wsgiapp
    return util.import_app(self.app_uri)
           ^^^^^^^^^^^^^^^^^^^^^^^^^^^^^
  File "/usr/local/lib/python3.11/site-packages/gunicorn/util.py", line 371, in import_app
    mod = importlib.import_module(module)
          ^^^^^^^^^^^^^^^^^^^^^^^^^^^^^^^
  File "/usr/local/lib/python3.11/importlib/__init__.py", line 126, in import_module
    return _bootstrap._gcd_import(name[level:], package, level)
           ^^^^^^^^^^^^^^^^^^^^^^^^^^^^^^^^^^^^^^^^^^^^^^^^^^^^
  File "<frozen importlib._bootstrap>", line 1204, in _gcd_import
  File "<frozen importlib._bootstrap>", line 1176, in _find_and_load
  File "<frozen importlib._bootstrap>", line 1147, in _find_and_load_unlocked
  File "<frozen importlib._bootstrap>", line 690, in _load_unlocked
  File "<frozen importlib._bootstrap_external>", line 940, in exec_module
  File "<frozen importlib._bootstrap>", line 241, in _call_with_frames_removed
  File "/app/app.py", line 167, in <module>
    analytics = PredictiveAnalytics()
                ^^^^^^^^^^^^^^^^^^^^^
  File "/app/app.py", line 59, in __init__
    os.makedirs(self.model_dir, exist_ok=True)
  File "<frozen os>", line 225, in makedirs
PermissionError: [Errno 13] Permission denied: 'models'
[2025-09-14 17:27:45 +0000] [7] [INFO] Worker exiting (pid: 7)
[2025-09-14 17:27:45 +0000] [8] [ERROR] Exception in worker process
Traceback (most recent call last):
  File "/usr/local/lib/python3.11/site-packages/gunicorn/arbiter.py", line 609, in spawn_worker
    worker.init_process()
  File "/usr/local/lib/python3.11/site-packages/gunicorn/workers/base.py", line 134, in init_process
    self.load_wsgi()
  File "/usr/local/lib/python3.11/site-packages/gunicorn/workers/base.py", line 146, in load_wsgi
    self.wsgi = self.app.wsgi()
                ^^^^^^^^^^^^^^^
  File "/usr/local/lib/python3.11/site-packages/gunicorn/app/base.py", line 67, in wsgi
    self.callable = self.load()
                    ^^^^^^^^^^^
  File "/usr/local/lib/python3.11/site-packages/gunicorn/app/wsgiapp.py", line 58, in load
    return self.load_wsgiapp()
           ^^^^^^^^^^^^^^^^^^^
  File "/usr/local/lib/python3.11/site-packages/gunicorn/app/wsgiapp.py", line 48, in load_wsgiapp
    return util.import_app(self.app_uri)
           ^^^^^^^^^^^^^^^^^^^^^^^^^^^^^
  File "/usr/local/lib/python3.11/site-packages/gunicorn/util.py", line 371, in import_app
    mod = importlib.import_module(module)
          ^^^^^^^^^^^^^^^^^^^^^^^^^^^^^^^
  File "/usr/local/lib/python3.11/importlib/__init__.py", line 126, in import_module
    return _bootstrap._gcd_import(name[level:], package, level)
           ^^^^^^^^^^^^^^^^^^^^^^^^^^^^^^^^^^^^^^^^^^^^^^^^^^^^
  File "<frozen importlib._bootstrap>", line 1204, in _gcd_import
  File "<frozen importlib._bootstrap>", line 1176, in _find_and_load
  File "<frozen importlib._bootstrap>", line 1147, in _find_and_load_unlocked
  File "<frozen importlib._bootstrap>", line 690, in _load_unlocked
  File "<frozen importlib._bootstrap_external>", line 940, in exec_module
  File "<frozen importlib._bootstrap>", line 241, in _call_with_frames_removed
  File "/app/app.py", line 167, in <module>
    analytics = PredictiveAnalytics()
                ^^^^^^^^^^^^^^^^^^^^^
  File "/app/app.py", line 59, in __init__
    os.makedirs(self.model_dir, exist_ok=True)
  File "<frozen os>", line 225, in makedirs
PermissionError: [Errno 13] Permission denied: 'models'
[2025-09-14 17:27:45 +0000] [8] [INFO] Worker exiting (pid: 8)
[2025-09-14 17:27:45 +0000] [6] [ERROR] Worker (pid:7) exited with code 3
[2025-09-14 17:27:45 +0000] [6] [ERROR] Worker (pid:8) was sent SIGTERM!
[2025-09-14 17:27:45 +0000] [6] [ERROR] Shutting down: Master
[2025-09-14 17:27:45 +0000] [6] [ERROR] Reason: Worker failed to boot.

i copied the 3 files from  analytics folder and uploaded to the hugging face space and it started running and building then this runtime error


vercel backend build  failed Logs
[23:00:45.795] Running build in Washington, D.C., USA (East) – iad1
[23:00:45.796] Build machine configuration: 2 cores, 8 GB
[23:00:45.813] Cloning github.com/p4r1ch4y/smart_city_os (Branch: feature/docker-nodb-inr, Commit: cf310dd)
[23:00:45.994] Previous build caches not available
[23:00:46.434] Cloning completed: 621.000ms
[23:00:46.478] Found .vercelignore
[23:00:46.493] Removed 75 ignored files defined in .vercelignore
[23:00:46.493]   /analytics/app.py
[23:00:46.493]   /analytics/Dockerfile
[23:00:46.493]   /analytics/requirements.txt
[23:00:46.493]   /anchor_project/Anchor.toml
[23:00:46.493]   /anchor_project/Cargo.lock
[23:00:46.493]   /anchor_project/Cargo.toml
[23:00:46.493]   /anchor_project/package.json
[23:00:46.493]   /anchor_project/programs/civic_ledger/Cargo.toml
[23:00:46.493]   /anchor_project/programs/civic_ledger/src/air_quality.rs
[23:00:46.493]   /anchor_project/programs/civic_ledger/src/contract.rs
[23:00:46.811] Running "vercel build"
[23:00:47.194] Vercel CLI 47.1.1
[23:00:47.881] Warning: Detected "engines": { "node": ">=16.0.0" } in your `package.json` that will automatically upgrade when a new major Node.js Version is released. Learn More: http://vercel.link/node-version
[23:00:47.885] Installing dependencies...
[23:01:23.020] npm warn deprecated inflight@1.0.6: This module is not supported, and leaks memory. Do not use it. Check out lru-cache if you want a good and tested way to coalesce async requests by a key value, which is much more comprehensive and powerful.
[23:01:23.340] npm warn deprecated glob@7.2.3: Glob versions prior to v9 are no longer supported
[23:01:24.118] npm warn deprecated superagent@8.1.2: Please upgrade to superagent v10.2.2+, see release notes at https://github.com/forwardemail/superagent/releases/tag/v10.2.2 - maintenance is supported by Forward Email @ https://forwardemail.net
[23:01:24.178] npm warn deprecated supertest@6.3.4: Please upgrade to supertest v7.1.3+, see release notes at https://github.com/forwardemail/supertest/releases/tag/v7.1.3 - maintenance is supported by Forward Email @ https://forwardemail.net
[23:01:28.571]
[23:01:28.571] added 624 packages in 40s
[23:01:28.571]
[23:01:28.571] 64 packages are looking for funding
[23:01:28.571]   run `npm fund` for details
[23:01:28.614] Running "npm run build"
[23:01:28.717]
[23:01:28.717] > smart-city-os@1.0.0 build
[23:01:28.717] > sh -c 'if [ "$BACKEND_ONLY" = "1" ]; then echo Skipping frontend build for backend project; else cd frontend && npm run build; fi'
[23:01:28.718]
[23:01:28.723] Skipping frontend build for backend project
[23:01:28.740] Error: No Output Directory named "public" found after the Build completed. Configure the Output Directory in your Project Settings. Alternatively, configure vercel.json#outputDirectory.
[23:01:28.741] Learn More: https://vercel.link/missing-public-directory


for vercel project this time i made the deafualt branch to feature/docker-nodb-inr
and pasted that backend only and cors env still build faileed